ERROR 2018-06-26 09:50:48,939 /Library/Frameworks/Python.framework/Versions/3.6/lib/python3.6/site-packages/django/core/handlers/exception.py exception.py exception handle_uncaught_exception 118: Internal Server Error: /admin/login/
Traceback (most recent call last):
  File "/Library/Frameworks/Python.framework/Versions/3.6/lib/python3.6/site-packages/django/db/backends/utils.py", line 85, in _execute
    return self.cursor.execute(sql, params)
  File "/Library/Frameworks/Python.framework/Versions/3.6/lib/python3.6/site-packages/django/db/backends/mysql/base.py", line 71, in execute
    return self.cursor.execute(query, args)
  File "/Library/Frameworks/Python.framework/Versions/3.6/lib/python3.6/site-packages/pymysql/cursors.py", line 170, in execute
    result = self._query(query)
  File "/Library/Frameworks/Python.framework/Versions/3.6/lib/python3.6/site-packages/pymysql/cursors.py", line 328, in _query
    conn.query(q)
  File "/Library/Frameworks/Python.framework/Versions/3.6/lib/python3.6/site-packages/pymysql/connections.py", line 893, in query
    self._affected_rows = self._read_query_result(unbuffered=unbuffered)
  File "/Library/Frameworks/Python.framework/Versions/3.6/lib/python3.6/site-packages/pymysql/connections.py", line 1103, in _read_query_result
    result.read()
  File "/Library/Frameworks/Python.framework/Versions/3.6/lib/python3.6/site-packages/pymysql/connections.py", line 1396, in read
    first_packet = self.connection._read_packet()
  File "/Library/Frameworks/Python.framework/Versions/3.6/lib/python3.6/site-packages/pymysql/connections.py", line 1059, in _read_packet
    packet.check_error()
  File "/Library/Frameworks/Python.framework/Versions/3.6/lib/python3.6/site-packages/pymysql/connections.py", line 384, in check_error
    err.raise_mysql_exception(self._data)
  File "/Library/Frameworks/Python.framework/Versions/3.6/lib/python3.6/site-packages/pymysql/err.py", line 109, in raise_mysql_exception
    raise errorclass(errno, errval)
pymysql.err.ProgrammingError: (1146, "Table 'homework.auth_user' doesn't exist")

The above exception was the direct cause of the following exception:

Traceback (most recent call last):
  File "/Library/Frameworks/Python.framework/Versions/3.6/lib/python3.6/site-packages/django/core/handlers/exception.py", line 35, in inner
    response = get_response(request)
  File "/Library/Frameworks/Python.framework/Versions/3.6/lib/python3.6/site-packages/django/core/handlers/base.py", line 128, in _get_response
    response = self.process_exception_by_middleware(e, request)
  File "/Library/Frameworks/Python.framework/Versions/3.6/lib/python3.6/site-packages/django/core/handlers/base.py", line 126, in _get_response
    response = wrapped_callback(request, *callback_args, **callback_kwargs)
  File "/Library/Frameworks/Python.framework/Versions/3.6/lib/python3.6/site-packages/django/views/decorators/cache.py", line 44, in _wrapped_view_func
    response = view_func(request, *args, **kwargs)
  File "/Library/Frameworks/Python.framework/Versions/3.6/lib/python3.6/site-packages/django/contrib/admin/sites.py", line 398, in login
    return LoginView.as_view(**defaults)(request)
  File "/Library/Frameworks/Python.framework/Versions/3.6/lib/python3.6/site-packages/django/views/generic/base.py", line 69, in view
    return self.dispatch(request, *args, **kwargs)
  File "/Library/Frameworks/Python.framework/Versions/3.6/lib/python3.6/site-packages/django/utils/decorators.py", line 62, in _wrapper
    return bound_func(*args, **kwargs)
  File "/Library/Frameworks/Python.framework/Versions/3.6/lib/python3.6/site-packages/django/views/decorators/debug.py", line 76, in sensitive_post_parameters_wrapper
    return view(request, *args, **kwargs)
  File "/Library/Frameworks/Python.framework/Versions/3.6/lib/python3.6/site-packages/django/utils/decorators.py", line 58, in bound_func
    return func.__get__(self, type(self))(*args2, **kwargs2)
  File "/Library/Frameworks/Python.framework/Versions/3.6/lib/python3.6/site-packages/django/utils/decorators.py", line 62, in _wrapper
    return bound_func(*args, **kwargs)
  File "/Library/Frameworks/Python.framework/Versions/3.6/lib/python3.6/site-packages/django/utils/decorators.py", line 142, in _wrapped_view
    response = view_func(request, *args, **kwargs)
  File "/Library/Frameworks/Python.framework/Versions/3.6/lib/python3.6/site-packages/django/utils/decorators.py", line 58, in bound_func
    return func.__get__(self, type(self))(*args2, **kwargs2)
  File "/Library/Frameworks/Python.framework/Versions/3.6/lib/python3.6/site-packages/django/utils/decorators.py", line 62, in _wrapper
    return bound_func(*args, **kwargs)
  File "/Library/Frameworks/Python.framework/Versions/3.6/lib/python3.6/site-packages/django/views/decorators/cache.py", line 44, in _wrapped_view_func
    response = view_func(request, *args, **kwargs)
  File "/Library/Frameworks/Python.framework/Versions/3.6/lib/python3.6/site-packages/django/utils/decorators.py", line 58, in bound_func
    return func.__get__(self, type(self))(*args2, **kwargs2)
  File "/Library/Frameworks/Python.framework/Versions/3.6/lib/python3.6/site-packages/django/contrib/auth/views.py", line 66, in dispatch
    return super().dispatch(request, *args, **kwargs)
  File "/Library/Frameworks/Python.framework/Versions/3.6/lib/python3.6/site-packages/django/views/generic/base.py", line 89, in dispatch
    return handler(request, *args, **kwargs)
  File "/Library/Frameworks/Python.framework/Versions/3.6/lib/python3.6/site-packages/django/views/generic/edit.py", line 141, in post
    if form.is_valid():
  File "/Library/Frameworks/Python.framework/Versions/3.6/lib/python3.6/site-packages/django/forms/forms.py", line 179, in is_valid
    return self.is_bound and not self.errors
  File "/Library/Frameworks/Python.framework/Versions/3.6/lib/python3.6/site-packages/django/forms/forms.py", line 174, in errors
    self.full_clean()
  File "/Library/Frameworks/Python.framework/Versions/3.6/lib/python3.6/site-packages/django/forms/forms.py", line 377, in full_clean
    self._clean_form()
  File "/Library/Frameworks/Python.framework/Versions/3.6/lib/python3.6/site-packages/django/forms/forms.py", line 404, in _clean_form
    cleaned_data = self.clean()
  File "/Library/Frameworks/Python.framework/Versions/3.6/lib/python3.6/site-packages/django/contrib/auth/forms.py", line 195, in clean
    self.user_cache = authenticate(self.request, username=username, password=password)
  File "/Library/Frameworks/Python.framework/Versions/3.6/lib/python3.6/site-packages/django/contrib/auth/__init__.py", line 70, in authenticate
    user = _authenticate_with_backend(backend, backend_path, request, credentials)
  File "/Library/Frameworks/Python.framework/Versions/3.6/lib/python3.6/site-packages/django/contrib/auth/__init__.py", line 116, in _authenticate_with_backend
    return backend.authenticate(*args, **credentials)
  File "/Library/Frameworks/Python.framework/Versions/3.6/lib/python3.6/site-packages/django/contrib/auth/backends.py", line 16, in authenticate
    user = UserModel._default_manager.get_by_natural_key(username)
  File "/Library/Frameworks/Python.framework/Versions/3.6/lib/python3.6/site-packages/django/contrib/auth/base_user.py", line 44, in get_by_natural_key
    return self.get(**{self.model.USERNAME_FIELD: username})
  File "/Library/Frameworks/Python.framework/Versions/3.6/lib/python3.6/site-packages/django/db/models/manager.py", line 82, in manager_method
    return getattr(self.get_queryset(), name)(*args, **kwargs)
  File "/Library/Frameworks/Python.framework/Versions/3.6/lib/python3.6/site-packages/django/db/models/query.py", line 397, in get
    num = len(clone)
  File "/Library/Frameworks/Python.framework/Versions/3.6/lib/python3.6/site-packages/django/db/models/query.py", line 254, in __len__
    self._fetch_all()
  File "/Library/Frameworks/Python.framework/Versions/3.6/lib/python3.6/site-packages/django/db/models/query.py", line 1179, in _fetch_all
    self._result_cache = list(self._iterable_class(self))
  File "/Library/Frameworks/Python.framework/Versions/3.6/lib/python3.6/site-packages/django/db/models/query.py", line 53, in __iter__
    results = compiler.execute_sql(chunked_fetch=self.chunked_fetch, chunk_size=self.chunk_size)
  File "/Library/Frameworks/Python.framework/Versions/3.6/lib/python3.6/site-packages/django/db/models/sql/compiler.py", line 1068, in execute_sql
    cursor.execute(sql, params)
  File "/Library/Frameworks/Python.framework/Versions/3.6/lib/python3.6/site-packages/django/db/backends/utils.py", line 100, in execute
    return super().execute(sql, params)
  File "/Library/Frameworks/Python.framework/Versions/3.6/lib/python3.6/site-packages/django/db/backends/utils.py", line 68, in execute
    return self._execute_with_wrappers(sql, params, many=False, executor=self._execute)
  File "/Library/Frameworks/Python.framework/Versions/3.6/lib/python3.6/site-packages/django/db/backends/utils.py", line 77, in _execute_with_wrappers
    return executor(sql, params, many, context)
  File "/Library/Frameworks/Python.framework/Versions/3.6/lib/python3.6/site-packages/django/db/backends/utils.py", line 85, in _execute
    return self.cursor.execute(sql, params)
  File "/Library/Frameworks/Python.framework/Versions/3.6/lib/python3.6/site-packages/django/db/utils.py", line 89, in __exit__
    raise dj_exc_value.with_traceback(traceback) from exc_value
  File "/Library/Frameworks/Python.framework/Versions/3.6/lib/python3.6/site-packages/django/db/backends/utils.py", line 85, in _execute
    return self.cursor.execute(sql, params)
  File "/Library/Frameworks/Python.framework/Versions/3.6/lib/python3.6/site-packages/django/db/backends/mysql/base.py", line 71, in execute
    return self.cursor.execute(query, args)
  File "/Library/Frameworks/Python.framework/Versions/3.6/lib/python3.6/site-packages/pymysql/cursors.py", line 170, in execute
    result = self._query(query)
  File "/Library/Frameworks/Python.framework/Versions/3.6/lib/python3.6/site-packages/pymysql/cursors.py", line 328, in _query
    conn.query(q)
  File "/Library/Frameworks/Python.framework/Versions/3.6/lib/python3.6/site-packages/pymysql/connections.py", line 893, in query
    self._affected_rows = self._read_query_result(unbuffered=unbuffered)
  File "/Library/Frameworks/Python.framework/Versions/3.6/lib/python3.6/site-packages/pymysql/connections.py", line 1103, in _read_query_result
    result.read()
  File "/Library/Frameworks/Python.framework/Versions/3.6/lib/python3.6/site-packages/pymysql/connections.py", line 1396, in read
    first_packet = self.connection._read_packet()
  File "/Library/Frameworks/Python.framework/Versions/3.6/lib/python3.6/site-packages/pymysql/connections.py", line 1059, in _read_packet
    packet.check_error()
  File "/Library/Frameworks/Python.framework/Versions/3.6/lib/python3.6/site-packages/pymysql/connections.py", line 384, in check_error
    err.raise_mysql_exception(self._data)
  File "/Library/Frameworks/Python.framework/Versions/3.6/lib/python3.6/site-packages/pymysql/err.py", line 109, in raise_mysql_exception
    raise errorclass(errno, errval)
django.db.utils.ProgrammingError: (1146, "Table 'homework.auth_user' doesn't exist")
ERROR 2018-06-26 09:50:49,100 /Library/Frameworks/Python.framework/Versions/3.6/lib/python3.6/site-packages/django/core/servers/basehttp.py basehttp.py basehttp log_message 124: "POST /admin/login/?next=/admin/ HTTP/1.1" 500 302095
